Workbook

Sheet Data Sources
B2: Sheet Name | C2: Data Sources
B3: Ticker List | C3: https://www.idx.co.id/id/data-pasar/data-saham/daftar-saham/ Sector & Industry : Probe YFInance
B4: Index & IHSG (IDX-IC) | C4: https://www.idx.co.id/id/data-pasar/data-saham/indeks-saham/
B5: Ownership 1% & Classification | C5: https://www.idx.co.id/id/perusahaan-tercatat/data-kepemilikan-saham/
B6: Konglo Index | C6: https://www.perplexity.ai/computer/a/1ec049c8-dfbf-4ae1-8034-45ddd8f97f91

Sheet TICKER LIST
A1: No. | B1: Ticker | C1: Company Name | D1: Listing Date | E1: Shares | F1: Listing Board | G1: Sector Index | H1: Sector | I1: Industry
A2: 1 | B2: MGLV | C2: NexAI Digital Infrastruktur Tb | D2: 08 Jun 2021 | E2: 1.904.883.411 | F2: Akselerasi | H2: Consumer Cyclical | I2: Furnishings, Fixtures & Appliances
A3: 2 | B3: TRUE | C3: Triniti Dinamik Tbk. | D3: 10 Jun 2021 | E3: 7.571.107.860 | F3: Pengembangan | G3: IDXPROPERT | H3: Real Estate | I3: Real Estate - Development
A4: 3 | B4: LABA | C4: Green Power Group Tbk. | D4: 10 Jun 2021 | E4: 1.103.402.553 | F4: Pengembangan | G4: IDXINDUST | H4: Basic Materials | I4: Steel
A5: 4 | B5: ARCI | C5: Archi Indonesia Tbk. | D5: 28 Jun 2021 | E5: 25.235.000.000 | F5: Pengembangan | G5: IDXBASIC | H5: Basic Materials | I5: Gold
A6: 5 | B6: IPAC | C6: Era Graharealty Tbk. | D6: 30 Jun 2021 | E6: 949.868.500 | F6: Akselerasi | H6: Real Estate | I6: Real Estate Services
A7: 6 | B7: MASB | C7: Bank Multiarta Sentosa Tbk. | D7: 30 Jun 2021 | E7: 1.387.737.233 | F7: Utama | G7: IDXFINANCE | H7: Financial Services | I7: Banks - Regional
A8: 7 | B8: BMHS | C8: Bundamedik Tbk. | D8: 06 Jul 2021 | E8: 8.603.416.176 | F8: Utama | G8: IDXHEALTH | H8: Healthcare | I8: Medical Care Facilities
A9: 8 | B9: FLMC | C9: Falmaco Nonwoven Industri Tbk. | D9: 08 Jul 2021 | E9: 781.250.000 | F9: Akselerasi | H9: Consumer Defensive | I9: Household & Personal Products
A10: 9 | B10: NICL | C10: PAM Mineral Tbk. | D10: 09 Jul 2021 | E10: 10.635.644.907 | F10: Pengembangan | G10: IDXBASIC | H10: Basic Materials | I10: Other Industrial Metals & Mining
A11: 10 | B11: UVCR | C11: Trimegah Karya Pratama Tbk. | D11: 27 Jul 2021 | E11: 2.000.144.838 | F11: Pengembangan | G11: IDXTECHNO | H11: Technology | I11: Software - Application
A12: 11 | B12: BUKA | C12: Bukalapak.com Tbk. | D12: 06 Agt 2021 | E12: 103.167.090.767 | F12: Ekonomi Baru | G12: IDXTECHNO | H12: Consumer Cyclical | I12: Internet Retail
A13: 12 | B13: HAIS | C13: Hasnur Internasional Shipping | D13: 01 Sep 2021 | E13: 2.626.250.000 | F13: Pengembangan | G13: IDXTRANS | H13: Industrials | I13: Marine Shipping
A14: 13 | B14: OILS | C14: Indo Oil Perkasa Tbk. | D14: 06 Sep 2021 | E14: 454.056.563 | F14: Pengembangan | G14: IDXNONCYC | H14: Consumer Defensive | I14: Packaged Foods
A15: 14 | B15: GPSO | C15: Geoprima Solusi Tbk. | D15: 06 Sep 2021 | E15: 733.415.103 | F15: Pengembangan | G15: IDXINDUST | H15: Technology | I15: Scientific & Technical Instruments
A16: 15 | B16: MCOL | C16: Prima Andalan Mandiri Tbk. | D16: 07 Sep 2021 | E16: 3.555.560.000 | F16: Utama | G16: IDXENERGY | H16: Energy | I16: Thermal Coal
A17: 16 | B17: RSGK | C17: Kedoya Adyaraya Tbk. | D17: 08 Sep 2021 | E17: 929.675.000 | F17: Pengembangan | G17: IDXHEALTH | H17: Healthcare | I17: Medical Care Facilities
A18: 17 | B18: RUNS | C18: Global Sukses Solusi Tbk. | D18: 08 Sep 2021 | E18: 983.557.875 | F18: Akselerasi | H18: Technology | I18: Software - Application
A19: 18 | B19: SBMA | C19: Surya Biru Murni Acetylene Tbk | D19: 08 Sep 2021 | E19: 929.926.282 | F19: Pengembangan | G19: IDXBASIC | H19: Basic Materials | I19: Chemicals
A20: 19 | B20: CMNT | C20: Cemindo Gemilang Tbk. | D20: 08 Sep 2021 | E20: 17.125.504.000 | F20: Pengembangan | G20: IDXBASIC | H20: Basic Materials | I20: Building Materials
A21: 20 | B21: GTSI | C21: GTS Internasional Tbk. | D21: 08 Sep 2021 | E21: 15.819.142.767 | F21: Pengembangan | G21: IDXENERGY | H21: Industrials | I21: Marine Shipping
A22: 21 | B22: IDEA | C22: Idea Indonesia Akademi Tbk. | D22: 09 Sep 2021 | E22: 1.062.437.500 | F22: Akselerasi | H22: Consumer Defensive | I22: Education & Training Services
A23: 22 | B23: KUAS | C23: Ace Oldfields Tbk. | D23: 25 Okt 2021 | E23: 1.292.808.150 | F23: Pengembangan | G23: IDXINDUST | H23: Industrials | I23: Building Products & Equipment
A24: 23 | B24: BOBA | C24: Formosa Ingredient Factory Tbk | D24: 01 Nov 2021 | E24: 1.155.750.000 | F24: Pengembangan | G24: IDXNONCYC | H24: Consumer Defensive | I24: Packaged Foods
A25: 24 | B25: MTEL | C25: Dayamitra Telekomunikasi Tbk. | D25: 22 Nov 2021 | E25: 83.559.677.444 | F25: Utama | G25: IDXINFRA | H25: Communication Services | I25: Telecom Services
A26: 25 | B26: DEPO | C26: Caturkarda Depo Bangunan Tbk. | D26: 25 Nov 2021 | E26: 6.790.000.000 | F26: Pengembangan | G26: IDXCYCLIC | H26: Consumer Cyclical | I26: Home Improvement Retail
A27: 26 | B27: BINO | C27: Perma Plasindo Tbk. | D27: 25 Nov 2021 | E27: 2.275.316.111 | F27: Pengembangan | G27: IDXINDUST | H27: Industrials | I27: Business Equipment & Supplies
A28: 27 | B28: CMRY | C28: Cisarua Mountain Dairy Tbk. | D28: 06 Des 2021 | E28: 7.934.683.000 | F28: Utama | G28: IDXNONCYC | H28: Consumer Defensive | I28: Packaged Foods
A29: 28 | B29: WGSH | C29: Wira Global Solusi Tbk. | D29: 06 Des 2021 | E29: 2.085.000.000 | F29: Akselerasi | H29: Technology | I29: Software - Infrastructure
A30: 29 | B30: TAYS | C30: Jaya Swarasa Agung Tbk. | D30: 06 Des 2021 | E30: 1.098.920.000 | F30: Pengembangan | G30: IDXNONCYC | H30: Consumer Defensive | I30: Packaged Foods
A31: 30 | B31: WMPP | C31: Widodo Makmur Perkasa Tbk. | D31: 06 Des 2021 | E31: 29.419.000.000 | F31: Pemantauan Khusus | G31: IDXNONCYC | H31: Industrials | I31: Conglomerates
A32: 31 | B32: RMKE | C32: RMK Energy Tbk. | D32: 07 Des 2021 | E32: 21.875.000.000 | F32: Utama | G32: IDXENERGY | H32: Energy | I32: Thermal Coal
A33: 32 | B33: OBMD | C33: OBM Drilchem Tbk. | D33: 08 Des 2021 | E33: 805.992.931 | F33: Pengembangan | G33: IDXBASIC | H33: Basic Materials | I33: Specialty Chemicals
A34: 33 | B34: AVIA | C34: Avia Avian Tbk. | D34: 09 Mar 2026 | E34: 61.953.555.600 | G34: IDXBASIC | H34: Basic Materials | I34: Specialty Chemicals
A35: 34 | B35: IPPE | C35: Indo Pureco Pratama Tbk. | D35: 09 Des 2021 | E35: 4.600.000.000 | F35: Pemantauan Khusus | G35: IDXNONCYC | H35: Consumer Defensive | I35: Packaged Foods
A36: 35 | B36: NASI | C36: Wahana Inti Makmur Tbk. | D36: 13 Des 2021 | E36: 807.400.000 | F36: Pengembangan | G36: IDXNONCYC | H36: Consumer Defensive | I36: Farm Products
A37: 36 | B37: BSML | C37: Bintang Samudera Mandiri Lines | D37: 16 Des 2021 | E37: 1.850.225.000 | F37: Pengembangan | G37: IDXENERGY | H37: Industrials | I37: Marine Shipping
A38: 37 | B38: DRMA | C38: Dharma Polimetal Tbk. | D38: 20 Des 2021 | E38: 4.705.882.300 | F38: Utama | G38: IDXCYCLIC | H38: Consumer Cyclical | I38: Auto Parts
A39: 38 | B39: ADMR | C39: Alamtri Minerals Indonesia Tbk | D39: 03 Jan 2022 | E39: 40.882.331.500 | F39: Utama | G39: IDXENERGY | H39: Basic Materials | I39: Coking Coal
A40: 39 | B40: SEMA | C40: Semacom Integrated Tbk. | D40: 10 Jan 2022 | E40: 1.347.258.842 | F40: Pengembangan | G40: IDXENERGY | H40: Industrials | I40: Specialty Industrial Machinery
...

Sheet OWNERSHIP 1%
A1: Date | B1: Ticker | C1: Company Name | D1: Investor Name | E1: Investor Classification | F1: Local / Foreign | G1: Nationality | H1: Domicile | I1: Holdings (Scripless) | J1: Holdings (Scrip) | K1: Total Holding Shares | L1: Percentage (%) | M1: Free Float (%) | N1: Classic HHI | O1: Concentration Ratio Top 1 (CR1) | P1: Concentration Ratio Top 3 (CR3) | Q1: Holder | R1: CCS | S1: Ownership Type | T1: CCS Category | U1: Dedup Flag (helper) | V1: Deduped % (helper) | W1: Rank in Code (helper) | X1: Tie-Broken % (helper)
A2: 46265 | B2: AADI | C2: ADARO ANDALAN INDONESIA Tbk | D2: PT PERSADA CAPITAL INVESTAMA | E2: Corporate | F2: L | H2: INDONESIA | I2: 119887170 | J2: 0 | K2: 119887170 | L2: 1.54 | M2: =IFERROR(_xlfn.XLOOKUP($B2,'Ownership Metrics'!$A:$A,'Ownership Metrics'!$B:$B),"") -> 20.3 | N2: =IFERROR(_xlfn.XLOOKUP($B2,'Ownership Metrics'!$A:$A,'Ownership Metrics'!$C:$C),"") -> 2013 | O2: =IFERROR(_xlfn.XLOOKUP($B2,'Ownership Metrics'!$A:$A,'Ownership Metrics'!$D:$D),"") -> 41.1 | P2: =IFERROR(_xlfn.XLOOKUP($B2,'Ownership Metrics'!$A:$A,'Ownership Metrics'!$E:$E),"") -> 62.3 | Q2: =IFERROR(_xlfn.XLOOKUP($B2,'Ownership Metrics'!$A:$A,'Ownership Metrics'!$F:$F),"") -> 10 | R2: =IFERROR(_xlfn.XLOOKUP($B2,'Ownership Metrics'!$A:$A,'Ownership Metrics'!$G:$G),"") -> 41 | S2: =IFERROR(_xlfn.XLOOKUP($B2,'Ownership Metrics'!$A:$A,'Ownership Metrics'!$H:$H),"") -> Oligopoli | T2: =IFERROR(_xlfn.XLOOKUP($B2,'Ownership Metrics'!$A:$A,'Ownership Metrics'!$I:$I),"") -> Sedang | U2: =IF(COUNTIFS($B$2:$B2,$B2,$D$2:$D2,$D2)=1,1,0) -> 1 | V2: =SUMIFS($L$2:$L$10000,$B$2:$B$10000,$B2,$D$2:$D$10000,$D2) -> 1.54 | W2: =COUNTIFS($B$2:$B$10000,$B2,$U$2:$U$10000,1,$X$2:$X$10000,">"&$X2)+1 -> 8 | X2: =$V2-(ROW()*0.0000000001) -> 1.54
A3: 46265 | B3: AADI | C3: ADARO ANDALAN INDONESIA Tbk | D3: SARATOGA INVESTAMA SEDAYA TBK | E3: Private Bank | F3: L | H3: INDONESIA | I3: 340897429 | J3: 0 | K3: 340897429 | L3: 4.38 | M3: =IFERROR(_xlfn.XLOOKUP($B3,'Ownership Metrics'!$A:$A,'Ownership Metrics'!$B:$B),"") -> 20.3 | N3: =IFERROR(_xlfn.XLOOKUP($B3,'Ownership Metrics'!$A:$A,'Ownership Metrics'!$C:$C),"") -> 2013 | O3: =IFERROR(_xlfn.XLOOKUP($B3,'Ownership Metrics'!$A:$A,'Ownership Metrics'!$D:$D),"") -> 41.1 | P3: =IFERROR(_xlfn.XLOOKUP($B3,'Ownership Metrics'!$A:$A,'Ownership Metrics'!$E:$E),"") -> 62.3 | Q3: =IFERROR(_xlfn.XLOOKUP($B3,'Ownership Metrics'!$A:$A,'Ownership Metrics'!$F:$F),"") -> 10 | R3: =IFERROR(_xlfn.XLOOKUP($B3,'Ownership Metrics'!$A:$A,'Ownership Metrics'!$G:$G),"") -> 41 | S3: =IFERROR(_xlfn.XLOOKUP($B3,'Ownership Metrics'!$A:$A,'Ownership Metrics'!$H:$H),"") -> Oligopoli | T3: =IFERROR(_xlfn.XLOOKUP($B3,'Ownership Metrics'!$A:$A,'Ownership Metrics'!$I:$I),"") -> Sedang | U3: =IF(COUNTIFS($B$2:$B3,$B3,$D$2:$D3,$D3)=1,1,0) -> 1 | V3: =SUMIFS($L$2:$L$10000,$B$2:$B$10000,$B3,$D$2:$D$10000,$D3) -> 4.38 | W3: =COUNTIFS($B$2:$B$10000,$B3,$U$2:$U$10000,1,$X$2:$X$10000,">"&$X3)+1 -> 4 | X3: =$V3-(ROW()*0.0000000001) -> 4.38
A4: 46265 | B4: AADI | C4: ADARO ANDALAN INDONESIA Tbk | D4: PT TRINUGRAHA THOHIR | E4: Corporate | F4: L | H4: INDONESIA | I4: 89926520 | J4: 0 | K4: 89926520 | L4: 1.15 | M4: =IFERROR(_xlfn.XLOOKUP($B4,'Ownership Metrics'!$A:$A,'Ownership Metrics'!$B:$B),"") -> 20.3 | N4: =IFERROR(_xlfn.XLOOKUP($B4,'Ownership Metrics'!$A:$A,'Ownership Metrics'!$C:$C),"") -> 2013 | O4: =IFERROR(_xlfn.XLOOKUP($B4,'Ownership Metrics'!$A:$A,'Ownership Metrics'!$D:$D),"") -> 41.1 | P4: =IFERROR(_xlfn.XLOOKUP($B4,'Ownership Metrics'!$A:$A,'Ownership Metrics'!$E:$E),"") -> 62.3 | Q4: =IFERROR(_xlfn.XLOOKUP($B4,'Ownership Metrics'!$A:$A,'Ownership Metrics'!$F:$F),"") -> 10 | R4: =IFERROR(_xlfn.XLOOKUP($B4,'Ownership Metrics'!$A:$A,'Ownership Metrics'!$G:$G),"") -> 41 | S4: =IFERROR(_xlfn.XLOOKUP($B4,'Ownership Metrics'!$A:$A,'Ownership Metrics'!$H:$H),"") -> Oligopoli | T4: =IFERROR(_xlfn.XLOOKUP($B4,'Ownership Metrics'!$A:$A,'Ownership Metrics'!$I:$I),"") -> Sedang | U4: =IF(COUNTIFS($B$2:$B4,$B4,$D$2:$D4,$D4)=1,1,0) -> 1 | V4: =SUMIFS($L$2:$L$10000,$B$2:$B$10000,$B4,$D$2:$D$10000,$D4) -> 1.15 | W4: =COUNTIFS($B$2:$B$10000,$B4,$U$2:$U$10000,1,$X$2:$X$10000,">"&$X4)+1 -> 10 | X4: =$V4-(ROW()*0.0000000001) -> 1.15
A5: 46265 | B5: AADI | C5: ADARO ANDALAN INDONESIA Tbk | D5: ADARO STRATEGIC INVESTMENTS | E5: Corporate | F5: L | H5: INDONESIA | I5: 3200142830 | J5: 0 | K5: 3200142830 | L5: 41.1 | M5: =IFERROR(_xlfn.XLOOKUP($B5,'Ownership Metrics'!$A:$A,'Ownership Metrics'!$B:$B),"") -> 20.3 | N5: =IFERROR(_xlfn.XLOOKUP($B5,'Ownership Metrics'!$A:$A,'Ownership Metrics'!$C:$C),"") -> 2013 | O5: =IFERROR(_xlfn.XLOOKUP($B5,'Ownership Metrics'!$A:$A,'Ownership Metrics'!$D:$D),"") -> 41.1 | P5: =IFERROR(_xlfn.XLOOKUP($B5,'Ownership Metrics'!$A:$A,'Ownership Metrics'!$E:$E),"") -> 62.3 | Q5: =IFERROR(_xlfn.XLOOKUP($B5,'Ownership Metrics'!$A:$A,'Ownership Metrics'!$F:$F),"") -> 10 | R5: =IFERROR(_xlfn.XLOOKUP($B5,'Ownership Metrics'!$A:$A,'Ownership Metrics'!$G:$G),"") -> 41 | S5: =IFERROR(_xlfn.XLOOKUP($B5,'Ownership Metrics'!$A:$A,'Ownership Metrics'!$H:$H),"") -> Oligopoli | T5: =IFERROR(_xlfn.XLOOKUP($B5,'Ownership Metrics'!$A:$A,'Ownership Metrics'!$I:$I),"") -> Sedang | U5: =IF(COUNTIFS($B$2:$B5,$B5,$D$2:$D5,$D5)=1,1,0) -> 1 | V5: =SUMIFS($L$2:$L$10000,$B$2:$B$10000,$B5,$D$2:$D$10000,$D5) -> 41.1 | W5: =COUNTIFS($B$2:$B$10000,$B5,$U$2:$U$10000,1,$X$2:$X$10000,">"&$X5)+1 -> 1 | X5: =$V5-(ROW()*0.0000000001) -> 41.1
A6: 46265 | B6: AADI | C6: ADARO ANDALAN INDONESIA Tbk | D6: ALAMTRI RESOURCES INDONESIA TBK PT | E6: Corporate | F6: L | H6: INDONESIA | I6: 1197023942 | J6: 0 | K6: 1197023942 | L6: 15.37 | M6: =IFERROR(_xlfn.XLOOKUP($B6,'Ownership Metrics'!$A:$A,'Ownership Metrics'!$B:$B),"") -> 20.3 | N6: =IFERROR(_xlfn.XLOOKUP($B6,'Ownership Metrics'!$A:$A,'Ownership Metrics'!$C:$C),"") -> 2013 | O6: =IFERROR(_xlfn.XLOOKUP($B6,'Ownership Metrics'!$A:$A,'Ownership Metrics'!$D:$D),"") -> 41.1 | P6: =IFERROR(_xlfn.XLOOKUP($B6,'Ownership Metrics'!$A:$A,'Ownership Metrics'!$E:$E),"") -> 62.3 | Q6: =IFERROR(_xlfn.XLOOKUP($B6,'Ownership Metrics'!$A:$A,'Ownership Metrics'!$F:$F),"") -> 10 | R6: =IFERROR(_xlfn.XLOOKUP($B6,'Ownership Metrics'!$A:$A,'Ownership Metrics'!$G:$G),"") -> 41 | S6: =IFERROR(_xlfn.XLOOKUP($B6,'Ownership Metrics'!$A:$A,'Ownership Metrics'!$H:$H),"") -> Oligopoli | T6: =IFERROR(_xlfn.XLOOKUP($B6,'Ownership Metrics'!$A:$A,'Ownership Metrics'!$I:$I),"") -> Sedang | U6: =IF(COUNTIFS($B$2:$B6,$B6,$D$2:$D6,$D6)=1,1,0) -> 1 | V6: =SUMIFS($L$2:$L$10000,$B$2:$B$10000,$B6,$D$2:$D$10000,$D6) -> 15.37 | W6: =COUNTIFS($B$2:$B$10000,$B6,$U$2:$U$10000,1,$X$2:$X$10000,">"&$X6)+1 -> 2 | X6: =$V6-(ROW()*0.0000000001) -> 15.37
A7: 46265 | B7: AADI | C7: ADARO ANDALAN INDONESIA Tbk | D7: FTAG INVESTMENT BANK LTD | E7: Financial Institutional | F7: F | H7: MALAYSIA | I7: 100722000 | J7: 0 | K7: 100722000 | L7: 1.29 | M7: =IFERROR(_xlfn.XLOOKUP($B7,'Ownership Metrics'!$A:$A,'Ownership Metrics'!$B:$B),"") -> 20.3 | N7: =IFERROR(_xlfn.XLOOKUP($B7,'Ownership Metrics'!$A:$A,'Ownership Metrics'!$C:$C),"") -> 2013 | O7: =IFERROR(_xlfn.XLOOKUP($B7,'Ownership Metrics'!$A:$A,'Ownership Metrics'!$D:$D),"") -> 41.1 | P7: =IFERROR(_xlfn.XLOOKUP($B7,'Ownership Metrics'!$A:$A,'Ownership Metrics'!$E:$E),"") -> 62.3 | Q7: =IFERROR(_xlfn.XLOOKUP($B7,'Ownership Metrics'!$A:$A,'Ownership Metrics'!$F:$F),"") -> 10 | R7: =IFERROR(_xlfn.XLOOKUP($B7,'Ownership Metrics'!$A:$A,'Ownership Metrics'!$G:$G),"") -> 41 | S7: =IFERROR(_xlfn.XLOOKUP($B7,'Ownership Metrics'!$A:$A,'Ownership Metrics'!$H:$H),"") -> Oligopoli | T7: =IFERROR(_xlfn.XLOOKUP($B7,'Ownership Metrics'!$A:$A,'Ownership Metrics'!$I:$I),"") -> Sedang | U7: =IF(COUNTIFS($B$2:$B7,$B7,$D$2:$D7,$D7)=1,1,0) -> 1 | V7: =SUMIFS($L$2:$L$10000,$B$2:$B$10000,$B7,$D$2:$D$10000,$D7) -> 1.29 | W7: =COUNTIFS($B$2:$B$10000,$B7,$U$2:$U$10000,1,$X$2:$X$10000,">"&$X7)+1 -> 9 | X7: =$V7-(ROW()*0.0000000001) -> 1.29
A8: 46265 | B8: AADI | C8: ADARO ANDALAN INDONESIA Tbk | D8: GARIBALDI THOHIR | E8: Individual | F8: L | G8: INDONESIAN | H8: INDONESIA | I8: 454011607 | J8: 0 | K8: 454011607 | L8: 5.83 | M8: =IFERROR(_xlfn.XLOOKUP($B8,'Ownership Metrics'!$A:$A,'Ownership Metrics'!$B:$B),"") -> 20.3 | N8: =IFERROR(_xlfn.XLOOKUP($B8,'Ownership Metrics'!$A:$A,'Ownership Metrics'!$C:$C),"") -> 2013 | O8: =IFERROR(_xlfn.XLOOKUP($B8,'Ownership Metrics'!$A:$A,'Ownership Metrics'!$D:$D),"") -> 41.1 | P8: =IFERROR(_xlfn.XLOOKUP($B8,'Ownership Metrics'!$A:$A,'Ownership Metrics'!$E:$E),"") -> 62.3 | Q8: =IFERROR(_xlfn.XLOOKUP($B8,'Ownership Metrics'!$A:$A,'Ownership Metrics'!$F:$F),"") -> 10 | R8: =IFERROR(_xlfn.XLOOKUP($B8,'Ownership Metrics'!$A:$A,'Ownership Metrics'!$G:$G),"") -> 41 | S8: =IFERROR(_xlfn.XLOOKUP($B8,'Ownership Metrics'!$A:$A,'Ownership Metrics'!$H:$H),"") -> Oligopoli | T8: =IFERROR(_xlfn.XLOOKUP($B8,'Ownership Metrics'!$A:$A,'Ownership Metrics'!$I:$I),"") -> Sedang | U8: =IF(COUNTIFS($B$2:$B8,$B8,$D$2:$D8,$D8)=1,1,0) -> 1 | V8: =SUMIFS($L$2:$L$10000,$B$2:$B$10000,$B8,$D$2:$D$10000,$D8) -> 5.83 | W8: =COUNTIFS($B$2:$B$10000,$B8,$U$2:$U$10000,1,$X$2:$X$10000,">"&$X8)+1 -> 3 | X8: =$V8-(ROW()*0.0000000001) -> 5.83
A9: 46265 | B9: AADI | C9: ADARO ANDALAN INDONESIA Tbk | D9: IR. T. PERMADI RACHMAT | E9: Individual | F9: L | G9: INDONESIAN | H9: INDONESIA | I9: 271164118 | J9: 0 | K9: 271164118 | L9: 3.48 | M9: =IFERROR(_xlfn.XLOOKUP($B9,'Ownership Metrics'!$A:$A,'Ownership Metrics'!$B:$B),"") -> 20.3 | N9: =IFERROR(_xlfn.XLOOKUP($B9,'Ownership Metrics'!$A:$A,'Ownership Metrics'!$C:$C),"") -> 2013 | O9: =IFERROR(_xlfn.XLOOKUP($B9,'Ownership Metrics'!$A:$A,'Ownership Metrics'!$D:$D),"") -> 41.1 | P9: =IFERROR(_xlfn.XLOOKUP($B9,'Ownership Metrics'!$A:$A,'Ownership Metrics'!$E:$E),"") -> 62.3 | Q9: =IFERROR(_xlfn.XLOOKUP($B9,'Ownership Metrics'!$A:$A,'Ownership Metrics'!$F:$F),"") -> 10 | R9: =IFERROR(_xlfn.XLOOKUP($B9,'Ownership Metrics'!$A:$A,'Ownership Metrics'!$G:$G),"") -> 41 | S9: =IFERROR(_xlfn.XLOOKUP($B9,'Ownership Metrics'!$A:$A,'Ownership Metrics'!$H:$H),"") -> Oligopoli | T9: =IFERROR(_xlfn.XLOOKUP($B9,'Ownership Metrics'!$A:$A,'Ownership Metrics'!$I:$I),"") -> Sedang | U9: =IF(COUNTIFS($B$2:$B9,$B9,$D$2:$D9,$D9)=1,1,0) -> 1 | V9: =SUMIFS($L$2:$L$10000,$B$2:$B$10000,$B9,$D$2:$D$10000,$D9) -> 3.48 | W9: =COUNTIFS($B$2:$B$10000,$B9,$U$2:$U$10000,1,$X$2:$X$10000,">"&$X9)+1 -> 6 | X9: =$V9-(ROW()*0.0000000001) -> 3.48
A10: 46265 | B10: AADI | C10: ADARO ANDALAN INDONESIA Tbk | D10: EDWIN SOERYADJAYA | E10: Individual | F10: L | G10: INDONESIAN | H10: INDONESIA | I10: 273955636 | J10: 0 | K10: 273955636 | L10: 3.52 | M10: =IFERROR(_xlfn.XLOOKUP($B10,'Ownership Metrics'!$A:$A,'Ownership Metrics'!$B:$B),"") -> 20.3 | N10: =IFERROR(_xlfn.XLOOKUP($B10,'Ownership Metrics'!$A:$A,'Ownership Metrics'!$C:$C),"") -> 2013 | O10: =IFERROR(_xlfn.XLOOKUP($B10,'Ownership Metrics'!$A:$A,'Ownership Metrics'!$D:$D),"") -> 41.1 | P10: =IFERROR(_xlfn.XLOOKUP($B10,'Ownership Metrics'!$A:$A,'Ownership Metrics'!$E:$E),"") -> 62.3 | Q10: =IFERROR(_xlfn.XLOOKUP($B10,'Ownership Metrics'!$A:$A,'Ownership Metrics'!$F:$F),"") -> 10 | R10: =IFERROR(_xlfn.XLOOKUP($B10,'Ownership Metrics'!$A:$A,'Ownership Metrics'!$G:$G),"") -> 41 | S10: =IFERROR(_xlfn.XLOOKUP($B10,'Ownership Metrics'!$A:$A,'Ownership Metrics'!$H:$H),"") -> Oligopoli | T10: =IFERROR(_xlfn.XLOOKUP($B10,'Ownership Metrics'!$A:$A,'Ownership Metrics'!$I:$I),"") -> Sedang | U10: =IF(COUNTIFS($B$2:$B10,$B10,$D$2:$D10,$D10)=1,1,0) -> 1 | V10: =SUMIFS($L$2:$L$10000,$B$2:$B$10000,$B10,$D$2:$D$10000,$D10) -> 3.52 | W10: =COUNTIFS($B$2:$B$10000,$B10,$U$2:$U$10000,1,$X$2:$X$10000,">"&$X10)+1 -> 5 | X10: =$V10-(ROW()*0.0000000001) -> 3.52
A11: 46265 | B11: AADI | C11: ADARO ANDALAN INDONESIA Tbk | D11: SANDIAGA SALAHUDDIN UNO | E11: Individual | F11: L | G11: INDONESIAN | H11: INDONESIA | I11: 159027175 | J11: 0 | K11: 159027175 | L11: 2.04 | M11: =IFERROR(_xlfn.XLOOKUP($B11,'Ownership Metrics'!$A:$A,'Ownership Metrics'!$B:$B),"") -> 20.3 | N11: =IFERROR(_xlfn.XLOOKUP($B11,'Ownership Metrics'!$A:$A,'Ownership Metrics'!$C:$C),"") -> 2013 | O11: =IFERROR(_xlfn.XLOOKUP($B11,'Ownership Metrics'!$A:$A,'Ownership Metrics'!$D:$D),"") -> 41.1 | P11: =IFERROR(_xlfn.XLOOKUP($B11,'Ownership Metrics'!$A:$A,'Ownership Metrics'!$E:$E),"") -> 62.3 | Q11: =IFERROR(_xlfn.XLOOKUP($B11,'Ownership Metrics'!$A:$A,'Ownership Metrics'!$F:$F),"") -> 10 | R11: =IFERROR(_xlfn.XLOOKUP($B11,'Ownership Metrics'!$A:$A,'Ownership Metrics'!$G:$G),"") -> 41 | S11: =IFERROR(_xlfn.XLOOKUP($B11,'Ownership Metrics'!$A:$A,'Ownership Metrics'!$H:$H),"") -> Oligopoli | T11: =IFERROR(_xlfn.XLOOKUP($B11,'Ownership Metrics'!$A:$A,'Ownership Metrics'!$I:$I),"") -> Sedang | U11: =IF(COUNTIFS($B$2:$B11,$B11,$D$2:$D11,$D11)=1,1,0) -> 1 | V11: =SUMIFS($L$2:$L$10000,$B$2:$B$10000,$B11,$D$2:$D$10000,$D11) -> 2.04 | W11: =COUNTIFS($B$2:$B$10000,$B11,$U$2:$U$10000,1,$X$2:$X$10000,">"&$X11)+1 -> 7 | X11: =$V11-(ROW()*0.0000000001) -> 2.04
A12: 46265 | B12: AALI | C12: ASTRA AGRO LESTARI Tbk | D12: PT ASTRA INTERNATIONAL TBK | E12: Corporate | F12: L | H12: INDONESIA | I12: 0 | J12: 1533682440 | K12: 1533682440 | L12: 79.68 | M12: =IFERROR(_xlfn.XLOOKUP($B12,'Ownership Metrics'!$A:$A,'Ownership Metrics'!$B:$B),"") -> 18.14 | N12: =IFERROR(_xlfn.XLOOKUP($B12,'Ownership Metrics'!$A:$A,'Ownership Metrics'!$C:$C),"") -> 6354 | O12: =IFERROR(_xlfn.XLOOKUP($B12,'Ownership Metrics'!$A:$A,'Ownership Metrics'!$D:$D),"") -> 79.68 | P12: =IFERROR(_xlfn.XLOOKUP($B12,'Ownership Metrics'!$A:$A,'Ownership Metrics'!$E:$E),"") -> 81.86 | Q12: =IFERROR(_xlfn.XLOOKUP($B12,'Ownership Metrics'!$A:$A,'Ownership Metrics'!$F:$F),"") -> 2 | R12: =IFERROR(_xlfn.XLOOKUP($B12,'Ownership Metrics'!$A:$A,'Ownership Metrics'!$G:$G),"") -> 76 | S12: =IFERROR(_xlfn.XLOOKUP($B12,'Ownership Metrics'!$A:$A,'Ownership Metrics'!$H:$H),"") -> Mayoritas | T12: =IFERROR(_xlfn.XLOOKUP($B12,'Ownership Metrics'!$A:$A,'Ownership Metrics'!$I:$I),"") -> Tinggi | U12: =IF(COUNTIFS($B$2:$B12,$B12,$D$2:$D12,$D12)=1,1,0) -> 1 | V12: =SUMIFS($L$2:$L$10000,$B$2:$B$10000,$B12,$D$2:$D$10000,$D12) -> 79.68 | W12: =COUNTIFS($B$2:$B$10000,$B12,$U$2:$U$10000,1,$X$2:$X$10000,">"&$X12)+1 -> 1 | X12: =$V12-(ROW()*0.0000000001) -> 79.68
A13: 46265 | B13: AALI | C13: ASTRA AGRO LESTARI Tbk | D13: DJS KETENAGAKERJAAN PROGRAM JAMINAN HARI TUA | E13: Insurance | F13: L | H13: INDONESIA | I13: 41979300 | J13: 0 | K13: 41979300 | L13: 2.18 | M13: =IFERROR(_xlfn.XLOOKUP($B13,'Ownership Metrics'!$A:$A,'Ownership Metrics'!$B:$B),"") -> 18.14 | N13: =IFERROR(_xlfn.XLOOKUP($B13,'Ownership Metrics'!$A:$A,'Ownership Metrics'!$C:$C),"") -> 6354 | O13: =IFERROR(_xlfn.XLOOKUP($B13,'Ownership Metrics'!$A:$A,'Ownership Metrics'!$D:$D),"") -> 79.68 | P13: =IFERROR(_xlfn.XLOOKUP($B13,'Ownership Metrics'!$A:$A,'Ownership Metrics'!$E:$E),"") -> 81.86 | Q13: =IFERROR(_xlfn.XLOOKUP($B13,'Ownership Metrics'!$A:$A,'Ownership Metrics'!$F:$F),"") -> 2 | R13: =IFERROR(_xlfn.XLOOKUP($B13,'Ownership Metrics'!$A:$A,'Ownership Metrics'!$G:$G),"") -> 76 | S13: =IFERROR(_xlfn.XLOOKUP($B13,'Ownership Metrics'!$A:$A,'Ownership Metrics'!$H:$H),"") -> Mayoritas | T13: =IFERROR(_xlfn.XLOOKUP($B13,'Ownership Metrics'!$A:$A,'Ownership Metrics'!$I:$I),"") -> Tinggi | U13: =IF(COUNTIFS($B$2:$B13,$B13,$D$2:$D13,$D13)=1,1,0) -> 1 | V13: =SUMIFS($L$2:$L$10000,$B$2:$B$10000,$B13,$D$2:$D$10000,$D13) -> 2.18 | W13: =COUNTIFS($B$2:$B$10000,$B13,$U$2:$U$10000,1,$X$2:$X$10000,">"&$X13)+1 -> 2 | X13: =$V13-(ROW()*0.0000000001) -> 2.18
A14: 46265 | B14: ABBA | C14: MAHAKA MEDIA Tbk | D14: YAYASAN BINA SEJAHTERA WARGA BULOG | I14: 0 | J14: 52975286 | K14: 52975286 | L14: 1.35 | M14: =IFERROR(_xlfn.XLOOKUP($B14,'Ownership Metrics'!$A:$A,'Ownership Metrics'!$B:$B),"") -> 25.33 | N14: =IFERROR(_xlfn.XLOOKUP($B14,'Ownership Metrics'!$A:$A,'Ownership Metrics'!$C:$C),"") -> 1915 | O14: =IFERROR(_xlfn.XLOOKUP($B14,'Ownership Metrics'!$A:$A,'Ownership Metrics'!$D:$D),"") -> 40.47 | P14: =IFERROR(_xlfn.XLOOKUP($B14,'Ownership Metrics'!$A:$A,'Ownership Metrics'!$E:$E),"") -> 61.43 | Q14: =IFERROR(_xlfn.XLOOKUP($B14,'Ownership Metrics'!$A:$A,'Ownership Metrics'!$F:$F),"") -> 10 | R14: =IFERROR(_xlfn.XLOOKUP($B14,'Ownership Metrics'!$A:$A,'Ownership Metrics'!$G:$G),"") -> 41 | S14: =IFERROR(_xlfn.XLOOKUP($B14,'Ownership Metrics'!$A:$A,'Ownership Metrics'!$H:$H),"") -> Oligopoli | T14: =IFERROR(_xlfn.XLOOKUP($B14,'Ownership Metrics'!$A:$A,'Ownership Metrics'!$I:$I),"") -> Sedang | U14: =IF(COUNTIFS($B$2:$B14,$B14,$D$2:$D14,$D14)=1,1,0) -> 1 | V14: =SUMIFS($L$2:$L$10000,$B$2:$B$10000,$B14,$D$2:$D$10000,$D14) -> 1.35 | W14: =COUNTIFS($B$2:$B$10000,$B14,$U$2:$U$10000,1,$X$2:$X$10000,">"&$X14)+1 -> 6 | X14: =$V14-(ROW()*0.0000000001) -> 1.35
A15: 46265 | B15: ABBA | C15: MAHAKA MEDIA Tbk | D15: YAYASAN ABDI BANGSA | I15: 0 | J15: 111372886 | K15: 111372886 | L15: 2.83 | M15: =IFERROR(_xlfn.XLOOKUP($B15,'Ownership Metrics'!$A:$A,'Ownership Metrics'!$B:$B),"") -> 25.33 | N15: =IFERROR(_xlfn.XLOOKUP($B15,'Ownership Metrics'!$A:$A,'Ownership Metrics'!$C:$C),"") -> 1915 | O15: =IFERROR(_xlfn.XLOOKUP($B15,'Ownership Metrics'!$A:$A,'Ownership Metrics'!$D:$D),"") -> 40.47 | P15: =IFERROR(_xlfn.XLOOKUP($B15,'Ownership Metrics'!$A:$A,'Ownership Metrics'!$E:$E),"") -> 61.43 | Q15: =IFERROR(_xlfn.XLOOKUP($B15,'Ownership Metrics'!$A:$A,'Ownership Metrics'!$F:$F),"") -> 10 | R15: =IFERROR(_xlfn.XLOOKUP($B15,'Ownership Metrics'!$A:$A,'Ownership Metrics'!$G:$G),"") -> 41 | S15: =IFERROR(_xlfn.XLOOKUP($B15,'Ownership Metrics'!$A:$A,'Ownership Metrics'!$H:$H),"") -> Oligopoli | T15: =IFERROR(_xlfn.XLOOKUP($B15,'Ownership Metrics'!$A:$A,'Ownership Metrics'!$I:$I),"") -> Sedang | U15: =IF(COUNTIFS($B$2:$B15,$B15,$D$2:$D15,$D15)=1,1,0) -> 1 | V15: =SUMIFS($L$2:$L$10000,$B$2:$B$10000,$B15,$D$2:$D$10000,$D15) -> 2.83 | W15: =COUNTIFS($B$2:$B$10000,$B15,$U$2:$U$10000,1,$X$2:$X$10000,">"&$X15)+1 -> 5 | X15: =$V15-(ROW()*0.0000000001) -> 2.83
A16: 46265 | B16: ABBA | C16: MAHAKA MEDIA Tbk | D16: MEDIAHUIS IRELAND LIMITED | I16: 0 | J16: 282886300 | K16: 282886300 | L16: 7.19 | M16: =IFERROR(_xlfn.XLOOKUP($B16,'Ownership Metrics'!$A:$A,'Ownership Metrics'!$B:$B),"") -> 25.33 | N16: =IFERROR(_xlfn.XLOOKUP($B16,'Ownership Metrics'!$A:$A,'Ownership Metrics'!$C:$C),"") -> 1915 | O16: =IFERROR(_xlfn.XLOOKUP($B16,'Ownership Metrics'!$A:$A,'Ownership Metrics'!$D:$D),"") -> 40.47 | P16: =IFERROR(_xlfn.XLOOKUP($B16,'Ownership Metrics'!$A:$A,'Ownership Metrics'!$E:$E),"") -> 61.43 | Q16: =IFERROR(_xlfn.XLOOKUP($B16,'Ownership Metrics'!$A:$A,'Ownership Metrics'!$F:$F),"") -> 10 | R16: =IFERROR(_xlfn.XLOOKUP($B16,'Ownership Metrics'!$A:$A,'Ownership Metrics'!$G:$G),"") -> 41 | S16: =IFERROR(_xlfn.XLOOKUP($B16,'Ownership Metrics'!$A:$A,'Ownership Metrics'!$H:$H),"") -> Oligopoli | T16: =IFERROR(_xlfn.XLOOKUP($B16,'Ownership Metrics'!$A:$A,'Ownership Metrics'!$I:$I),"") -> Sedang | U16: =IF(COUNTIFS($B$2:$B16,$B16,$D$2:$D16,$D16)=1,1,0) -> 1 | V16: =SUMIFS($L$2:$L$10000,$B$2:$B$10000,$B16,$D$2:$D$10000,$D16) -> 7.19 | W16: =COUNTIFS($B$2:$B$10000,$B16,$U$2:$U$10000,1,$X$2:$X$10000,">"&$X16)+1 -> 3 | X16: =$V16-(ROW()*0.0000000001) -> 7.19
A17: 46265 | B17: ABBA | C17: MAHAKA MEDIA Tbk | D17: PT BEYOND MEDIA | E17: Private Equity | F17: L | H17: INDONESIA | I17: 1592831618 | J17: 0 | K17: 1592831618 | L17: 40.47 | M17: =IFERROR(_xlfn.XLOOKUP($B17,'Ownership Metrics'!$A:$A,'Ownership Metrics'!$B:$B),"") -> 25.33 | N17: =IFERROR(_xlfn.XLOOKUP($B17,'Ownership Metrics'!$A:$A,'Ownership Metrics'!$C:$C),"") -> 1915 | O17: =IFERROR(_xlfn.XLOOKUP($B17,'Ownership Metrics'!$A:$A,'Ownership Metrics'!$D:$D),"") -> 40.47 | P17: =IFERROR(_xlfn.XLOOKUP($B17,'Ownership Metrics'!$A:$A,'Ownership Metrics'!$E:$E),"") -> 61.43 | Q17: =IFERROR(_xlfn.XLOOKUP($B17,'Ownership Metrics'!$A:$A,'Ownership Metrics'!$F:$F),"") -> 10 | R17: =IFERROR(_xlfn.XLOOKUP($B17,'Ownership Metrics'!$A:$A,'Ownership Metrics'!$G:$G),"") -> 41 | S17: =IFERROR(_xlfn.XLOOKUP($B17,'Ownership Metrics'!$A:$A,'Ownership Metrics'!$H:$H),"") -> Oligopoli | T17: =IFERROR(_xlfn.XLOOKUP($B17,'Ownership Metrics'!$A:$A,'Ownership Metrics'!$I:$I),"") -> Sedang | U17: =IF(COUNTIFS($B$2:$B17,$B17,$D$2:$D17,$D17)=1,1,0) -> 1 | V17: =SUMIFS($L$2:$L$10000,$B$2:$B$10000,$B17,$D$2:$D$10000,$D17) -> 40.47 | W17: =COUNTIFS($B$2:$B$10000,$B17,$U$2:$U$10000,1,$X$2:$X$10000,">"&$X17)+1 -> 1 | X17: =$V17-(ROW()*0.0000000001) -> 40.47
A18: 46265 | B18: ABBA | C18: MAHAKA MEDIA Tbk | D18: PT.Grid One Media | E18: Corporate | F18: L | H18: INDONESIA | I18: 43791628 | J18: 0 | K18: 43791628 | L18: 1.11 | M18: =IFERROR(_xlfn.XLOOKUP($B18,'Ownership Metrics'!$A:$A,'Ownership Metrics'!$B:$B),"") -> 25.33 | N18: =IFERROR(_xlfn.XLOOKUP($B18,'Ownership Metrics'!$A:$A,'Ownership Metrics'!$C:$C),"") -> 1915 | O18: =IFERROR(_xlfn.XLOOKUP($B18,'Ownership Metrics'!$A:$A,'Ownership Metrics'!$D:$D),"") -> 40.47 | P18: =IFERROR(_xlfn.XLOOKUP($B18,'Ownership Metrics'!$A:$A,'Ownership Metrics'!$E:$E),"") -> 61.43 | Q18: =IFERROR(_xlfn.XLOOKUP($B18,'Ownership Metrics'!$A:$A,'Ownership Metrics'!$F:$F),"") -> 10 | R18: =IFERROR(_xlfn.XLOOKUP($B18,'Ownership Metrics'!$A:$A,'Ownership Metrics'!$G:$G),"") -> 41 | S18: =IFERROR(_xlfn.XLOOKUP($B18,'Ownership Metrics'!$A:$A,'Ownership Metrics'!$H:$H),"") -> Oligopoli | T18: =IFERROR(_xlfn.XLOOKUP($B18,'Ownership Metrics'!$A:$A,'Ownership Metrics'!$I:$I),"") -> Sedang | U18: =IF(COUNTIFS($B$2:$B18,$B18,$D$2:$D18,$D18)=1,1,0) -> 1 | V18: =SUMIFS($L$2:$L$10000,$B$2:$B$10000,$B18,$D$2:$D$10000,$D18) -> 1.11 | W18: =COUNTIFS($B$2:$B$10000,$B18,$U$2:$U$10000,1,$X$2:$X$10000,">"&$X18)+1 -> 8 | X18: =$V18-(ROW()*0.0000000001) -> 1.11
A19: 46265 | B19: ABBA | C19: MAHAKA MEDIA Tbk | D19: SOLIC KREASI BARU PT | E19: Corporate | F19: L | H19: INDONESIA | I19: 542042122 | J19: 0 | K19: 542042122 | L19: 13.77 | M19: =IFERROR(_xlfn.XLOOKUP($B19,'Ownership Metrics'!$A:$A,'Ownership Metrics'!$B:$B),"") -> 25.33 | N19: =IFERROR(_xlfn.XLOOKUP($B19,'Ownership Metrics'!$A:$A,'Ownership Metrics'!$C:$C),"") -> 1915 | O19: =IFERROR(_xlfn.XLOOKUP($B19,'Ownership Metrics'!$A:$A,'Ownership Metrics'!$D:$D),"") -> 40.47 | P19: =IFERROR(_xlfn.XLOOKUP($B19,'Ownership Metrics'!$A:$A,'Ownership Metrics'!$E:$E),"") -> 61.43 | Q19: =IFERROR(_xlfn.XLOOKUP($B19,'Ownership Metrics'!$A:$A,'Ownership Metrics'!$F:$F),"") -> 10 | R19: =IFERROR(_xlfn.XLOOKUP($B19,'Ownership Metrics'!$A:$A,'Ownership Metrics'!$G:$G),"") -> 41 | S19: =IFERROR(_xlfn.XLOOKUP($B19,'Ownership Metrics'!$A:$A,'Ownership Metrics'!$H:$H),"") -> Oligopoli | T19: =IFERROR(_xlfn.XLOOKUP($B19,'Ownership Metrics'!$A:$A,'Ownership Metrics'!$I:$I),"") -> Sedang | U19: =IF(COUNTIFS($B$2:$B19,$B19,$D$2:$D19,$D19)=1,1,0) -> 1 | V19: =SUMIFS($L$2:$L$10000,$B$2:$B$10000,$B19,$D$2:$D$10000,$D19) -> 13.77 | W19: =COUNTIFS($B$2:$B$10000,$B19,$U$2:$U$10000,1,$X$2:$X$10000,">"&$X19)+1 -> 2 | X19: =$V19-(ROW()*0.0000000001) -> 13.77
A20: 46265 | B20: ABBA | C20: MAHAKA MEDIA Tbk | D20: KAIROS EKSPRES INTERNASIONAL PT | E20: Corporate | F20: L | H20: INDONESIA | I20: 52362500 | J20: 0 | K20: 52362500 | L20: 1.33 | M20: =IFERROR(_xlfn.XLOOKUP($B20,'Ownership Metrics'!$A:$A,'Ownership Metrics'!$B:$B),"") -> 25.33 | N20: =IFERROR(_xlfn.XLOOKUP($B20,'Ownership Metrics'!$A:$A,'Ownership Metrics'!$C:$C),"") -> 1915 | O20: =IFERROR(_xlfn.XLOOKUP($B20,'Ownership Metrics'!$A:$A,'Ownership Metrics'!$D:$D),"") -> 40.47 | P20: =IFERROR(_xlfn.XLOOKUP($B20,'Ownership Metrics'!$A:$A,'Ownership Metrics'!$E:$E),"") -> 61.43 | Q20: =IFERROR(_xlfn.XLOOKUP($B20,'Ownership Metrics'!$A:$A,'Ownership Metrics'!$F:$F),"") -> 10 | R20: =IFERROR(_xlfn.XLOOKUP($B20,'Ownership Metrics'!$A:$A,'Ownership Metrics'!$G:$G),"") -> 41 | S20: =IFERROR(_xlfn.XLOOKUP($B20,'Ownership Metrics'!$A:$A,'Ownership Metrics'!$H:$H),"") -> Oligopoli | T20: =IFERROR(_xlfn.XLOOKUP($B20,'Ownership Metrics'!$A:$A,'Ownership Metrics'!$I:$I),"") -> Sedang | U20: =IF(COUNTIFS($B$2:$B20,$B20,$D$2:$D20,$D20)=1,1,0) -> 1 | V20: =SUMIFS($L$2:$L$10000,$B$2:$B$10000,$B20,$D$2:$D$10000,$D20) -> 1.33 | W20: =COUNTIFS($B$2:$B$10000,$B20,$U$2:$U$10000,1,$X$2:$X$10000,">"&$X20)+1 -> 7 | X20: =$V20-(ROW()*0.0000000001) -> 1.33
A21: 46265 | B21: ABBA | C21: MAHAKA MEDIA Tbk | D21: PEARL HILL INVESTMENTS LTD | E21: Financial Institutional | F21: F | H21: VIRGIN ISLANDS, BRITISH | I21: 39999999 | J21: 0 | K21: 39999999 | L21: 1.02 | M21: =IFERROR(_xlfn.XLOOKUP($B21,'Ownership Metrics'!$A:$A,'Ownership Metrics'!$B:$B),"") -> 25.33 | N21: =IFERROR(_xlfn.XLOOKUP($B21,'Ownership Metrics'!$A:$A,'Ownership Metrics'!$C:$C),"") -> 1915 | O21: =IFERROR(_xlfn.XLOOKUP($B21,'Ownership Metrics'!$A:$A,'Ownership Metrics'!$D:$D),"") -> 40.47 | P21: =IFERROR(_xlfn.XLOOKUP($B21,'Ownership Metrics'!$A:$A,'Ownership Metrics'!$E:$E),"") -> 61.43 | Q21: =IFERROR(_xlfn.XLOOKUP($B21,'Ownership Metrics'!$A:$A,'Ownership Metrics'!$F:$F),"") -> 10 | R21: =IFERROR(_xlfn.XLOOKUP($B21,'Ownership Metrics'!$A:$A,'Ownership Metrics'!$G:$G),"") -> 41 | S21: =IFERROR(_xlfn.XLOOKUP($B21,'Ownership Metrics'!$A:$A,'Ownership Metrics'!$H:$H),"") -> Oligopoli | T21: =IFERROR(_xlfn.XLOOKUP($B21,'Ownership Metrics'!$A:$A,'Ownership Metrics'!$I:$I),"") -> Sedang | U21: =IF(COUNTIFS($B$2:$B21,$B21,$D$2:$D21,$D21)=1,1,0) -> 1 | V21: =SUMIFS($L$2:$L$10000,$B$2:$B$10000,$B21,$D$2:$D$10000,$D21) -> 1.02 | W21: =COUNTIFS($B$2:$B$10000,$B21,$U$2:$U$10000,1,$X$2:$X$10000,">"&$X21)+1 -> 10 | X21: =$V21-(ROW()*0.0000000001) -> 1.02
A22: 46265 | B22: ABBA | C22: MAHAKA MEDIA Tbk | D22: TJEN FOENG FA | E22: Individual | F22: L | G22: INDONESIAN | H22: INDONESIA | I22: 41856300 | J22: 0 | K22: 41856300 | L22: 1.06 | M22: =IFERROR(_xlfn.XLOOKUP($B22,'Ownership Metrics'!$A:$A,'Ownership Metrics'!$B:$B),"") -> 25.33 | N22: =IFERROR(_xlfn.XLOOKUP($B22,'Ownership Metrics'!$A:$A,'Ownership Metrics'!$C:$C),"") -> 1915 | O22: =IFERROR(_xlfn.XLOOKUP($B22,'Ownership Metrics'!$A:$A,'Ownership Metrics'!$D:$D),"") -> 40.47 | P22: =IFERROR(_xlfn.XLOOKUP($B22,'Ownership Metrics'!$A:$A,'Ownership Metrics'!$E:$E),"") -> 61.43 | Q22: =IFERROR(_xlfn.XLOOKUP($B22,'Ownership Metrics'!$A:$A,'Ownership Metrics'!$F:$F),"") -> 10 | R22: =IFERROR(_xlfn.XLOOKUP($B22,'Ownership Metrics'!$A:$A,'Ownership Metrics'!$G:$G),"") -> 41 | S22: =IFERROR(_xlfn.XLOOKUP($B22,'Ownership Metrics'!$A:$A,'Ownership Metrics'!$H:$H),"") -> Oligopoli | T22: =IFERROR(_xlfn.XLOOKUP($B22,'Ownership Metrics'!$A:$A,'Ownership Metrics'!$I:$I),"") -> Sedang | U22: =IF(COUNTIFS($B$2:$B22,$B22,$D$2:$D22,$D22)=1,1,0) -> 1 | V22: =SUMIFS($L$2:$L$10000,$B$2:$B$10000,$B22,$D$2:$D$10000,$D22) -> 1.06 | W22: =COUNTIFS($B$2:$B$10000,$B22,$U$2:$U$10000,1,$X$2:$X$10000,">"&$X22)+1 -> 9 | X22: =$V22-(ROW()*0.0000000001) -> 1.06
A23: 46265 | B23: ABBA | C23: MAHAKA MEDIA Tbk | D23: DRS. WINARTO | E23: Individual | F23: L | G23: INDONESIAN | I23: 178745400 | J23: 0 | K23: 178745400 | L23: 4.54 | M23: =IFERROR(_xlfn.XLOOKUP($B23,'Ownership Metrics'!$A:$A,'Ownership Metrics'!$B:$B),"") -> 25.33 | N23: =IFERROR(_xlfn.XLOOKUP($B23,'Ownership Metrics'!$A:$A,'Ownership Metrics'!$C:$C),"") -> 1915 | O23: =IFERROR(_xlfn.XLOOKUP($B23,'Ownership Metrics'!$A:$A,'Ownership Metrics'!$D:$D),"") -> 40.47 | P23: =IFERROR(_xlfn.XLOOKUP($B23,'Ownership Metrics'!$A:$A,'Ownership Metrics'!$E:$E),"") -> 61.43 | Q23: =IFERROR(_xlfn.XLOOKUP($B23,'Ownership Metrics'!$A:$A,'Ownership Metrics'!$F:$F),"") -> 10 | R23: =IFERROR(_xlfn.XLOOKUP($B23,'Ownership Metrics'!$A:$A,'Ownership Metrics'!$G:$G),"") -> 41 | S23: =IFERROR(_xlfn.XLOOKUP($B23,'Ownership Metrics'!$A:$A,'Ownership Metrics'!$H:$H),"") -> Oligopoli | T23: =IFERROR(_xlfn.XLOOKUP($B23,'Ownership Metrics'!$A:$A,'Ownership Metrics'!$I:$I),"") -> Sedang | U23: =IF(COUNTIFS($B$2:$B23,$B23,$D$2:$D23,$D23)=1,1,0) -> 1 | V23: =SUMIFS($L$2:$L$10000,$B$2:$B$10000,$B23,$D$2:$D$10000,$D23) -> 4.54 | W23: =COUNTIFS($B$2:$B$10000,$B23,$U$2:$U$10000,1,$X$2:$X$10000,">"&$X23)+1 -> 4 | X23: =$V23-(ROW()*0.0000000001) -> 4.54
A24: 46265 | B24: ABDA | C24: ASURANSI BINA DANA ARTA Tbk | D24: SKYLIGHT INVESTMENT LTD | E24: Private Equity | F24: F | H24: CAYMAN ISLANDS | I24: 21728234 | J24: 0 | K24: 21728234 | L24: 3.5 | M24: =IFERROR(_xlfn.XLOOKUP($B24,'Ownership Metrics'!$A:$A,'Ownership Metrics'!$B:$B),"") -> 0.32 | N24: =IFERROR(_xlfn.XLOOKUP($B24,'Ownership Metrics'!$A:$A,'Ownership Metrics'!$C:$C),"") -> 7584 | O24: =IFERROR(_xlfn.XLOOKUP($B24,'Ownership Metrics'!$A:$A,'Ownership Metrics'!$D:$D),"") -> 86.76 | P24: =IFERROR(_xlfn.XLOOKUP($B24,'Ownership Metrics'!$A:$A,'Ownership Metrics'!$E:$E),"") -> 96.18 | Q24: =IFERROR(_xlfn.XLOOKUP($B24,'Ownership Metrics'!$A:$A,'Ownership Metrics'!$F:$F),"") -> 4 | R24: =IFERROR(_xlfn.XLOOKUP($B24,'Ownership Metrics'!$A:$A,'Ownership Metrics'!$G:$G),"") -> 85 | S24: =IFERROR(_xlfn.XLOOKUP($B24,'Ownership Metrics'!$A:$A,'Ownership Metrics'!$H:$H),"") -> Mayoritas | T24: =IFERROR(_xlfn.XLOOKUP($B24,'Ownership Metrics'!$A:$A,'Ownership Metrics'!$I:$I),"") -> Tinggi | U24: =IF(COUNTIFS($B$2:$B24,$B24,$D$2:$D24,$D24)=1,1,0) -> 1 | V24: =SUMIFS($L$2:$L$10000,$B$2:$B$10000,$B24,$D$2:$D$10000,$D24) -> 3.5 | W24: =COUNTIFS($B$2:$B$10000,$B24,$U$2:$U$10000,1,$X$2:$X$10000,">"&$X24)+1 -> 4 | X24: =$V24-(ROW()*0.0000000001) -> 3.5
A25: 46265 | B25: ABDA | C25: ASURANSI BINA DANA ARTA Tbk | D25: DBS BANK LTD. | E25: Private Bank | F25: F | H25: SINGAPORE | I25: 28000000 | J25: 0 | K25: 28000000 | L25: 4.51 | M25: =IFERROR(_xlfn.XLOOKUP($B25,'Ownership Metrics'!$A:$A,'Ownership Metrics'!$B:$B),"") -> 0.32 | N25: =IFERROR(_xlfn.XLOOKUP($B25,'Ownership Metrics'!$A:$A,'Ownership Metrics'!$C:$C),"") -> 7584 | O25: =IFERROR(_xlfn.XLOOKUP($B25,'Ownership Metrics'!$A:$A,'Ownership Metrics'!$D:$D),"") -> 86.76 | P25: =IFERROR(_xlfn.XLOOKUP($B25,'Ownership Metrics'!$A:$A,'Ownership Metrics'!$E:$E),"") -> 96.18 | Q25: =IFERROR(_xlfn.XLOOKUP($B25,'Ownership Metrics'!$A:$A,'Ownership Metrics'!$F:$F),"") -> 4 | R25: =IFERROR(_xlfn.XLOOKUP($B25,'Ownership Metrics'!$A:$A,'Ownership Metrics'!$G:$G),"") -> 85 | S25: =IFERROR(_xlfn.XLOOKUP($B25,'Ownership Metrics'!$A:$A,'Ownership Metrics'!$H:$H),"") -> Mayoritas | T25: =IFERROR(_xlfn.XLOOKUP($B25,'Ownership Metrics'!$A:$A,'Ownership Metrics'!$I:$I),"") -> Tinggi | U25: =IF(COUNTIFS($B$2:$B25,$B25,$D$2:$D25,$D25)=1,1,0) -> 1 | V25: =SUMIFS($L$2:$L$10000,$B$2:$B$10000,$B25,$D$2:$D$10000,$D25) -> 4.51 | W25: =COUNTIFS($B$2:$B$10000,$B25,$U$2:$U$10000,1,$X$2:$X$10000,">"&$X25)+1 -> 3 | X25: =$V25-(ROW()*0.0000000001) -> 4.51
A26: 46265 | B26: ABDA | C26: ASURANSI BINA DANA ARTA Tbk | D26: OONA INDONESIA PTE LTD | E26: Insurance | F26: F | H26: SINGAPORE | I26: 538604204 | J26: 0 | K26: 538604204 | L26: 86.76 | M26: =IFERROR(_xlfn.XLOOKUP($B26,'Ownership Metrics'!$A:$A,'Ownership Metrics'!$B:$B),"") -> 0.32 | N26: =IFERROR(_xlfn.XLOOKUP($B26,'Ownership Metrics'!$A:$A,'Ownership Metrics'!$C:$C),"") -> 7584 | O26: =IFERROR(_xlfn.XLOOKUP($B26,'Ownership Metrics'!$A:$A,'Ownership Metrics'!$D:$D),"") -> 86.76 | P26: =IFERROR(_xlfn.XLOOKUP($B26,'Ownership Metrics'!$A:$A,'Ownership Metrics'!$E:$E),"") -> 96.18 | Q26: =IFERROR(_xlfn.XLOOKUP($B26,'Ownership Metrics'!$A:$A,'Ownership Metrics'!$F:$F),"") -> 4 | R26: =IFERROR(_xlfn.XLOOKUP($B26,'Ownership Metrics'!$A:$A,'Ownership Metrics'!$G:$G),"") -> 85 | S26: =IFERROR(_xlfn.XLOOKUP($B26,'Ownership Metrics'!$A:$A,'Ownership Metrics'!$H:$H),"") -> Mayoritas | T26: =IFERROR(_xlfn.XLOOKUP($B26,'Ownership Metrics'!$A:$A,'Ownership Metrics'!$I:$I),"") -> Tinggi | U26: =IF(COUNTIFS($B$2:$B26,$B26,$D$2:$D26,$D26)=1,1,0) -> 1 | V26: =SUMIFS($L$2:$L$10000,$B$2:$B$10000,$B26,$D$2:$D$10000,$D26) -> 86.76 | W26: =COUNTIFS($B$2:$B$10000,$B26,$U$2:$U$10000,1,$X$2:$X$10000,">"&$X26)+1 -> 1 | X26: =$V26-(ROW()*0.0000000001) -> 86.76
A27: 46265 | B27: ABDA | C27: ASURANSI BINA DANA ARTA Tbk | D27: MAYBANK SECURITIES PTE. LTD. | E27: Securities Company | F27: F | H27: SINGAPORE | I27: 30499400 | J27: 0 | K27: 30499400 | L27: 4.91 | M27: =IFERROR(_xlfn.XLOOKUP($B27,'Ownership Metrics'!$A:$A,'Ownership Metrics'!$B:$B),"") -> 0.32 | N27: =IFERROR(_xlfn.XLOOKUP($B27,'Ownership Metrics'!$A:$A,'Ownership Metrics'!$C:$C),"") -> 7584 | O27: =IFERROR(_xlfn.XLOOKUP($B27,'Ownership Metrics'!$A:$A,'Ownership Metrics'!$D:$D),"") -> 86.76 | P27: =IFERROR(_xlfn.XLOOKUP($B27,'Ownership Metrics'!$A:$A,'Ownership Metrics'!$E:$E),"") -> 96.18 | Q27: =IFERROR(_xlfn.XLOOKUP($B27,'Ownership Metrics'!$A:$A,'Ownership Metrics'!$F:$F),"") -> 4 | R27: =IFERROR(_xlfn.XLOOKUP($B27,'Ownership Metrics'!$A:$A,'Ownership Metrics'!$G:$G),"") -> 85 | S27: =IFERROR(_xlfn.XLOOKUP($B27,'Ownership Metrics'!$A:$A,'Ownership Metrics'!$H:$H),"") -> Mayoritas | T27: =IFERROR(_xlfn.XLOOKUP($B27,'Ownership Metrics'!$A:$A,'Ownership Metrics'!$I:$I),"") -> Tinggi | U27: =IF(COUNTIFS($B$2:$B27,$B27,$D$2:$D27,$D27)=1,1,0) -> 1 | V27: =SUMIFS($L$2:$L$10000,$B$2:$B$10000,$B27,$D$2:$D$10000,$D27) -> 4.91 | W27: =COUNTIFS($B$2:$B$10000,$B27,$U$2:$U$10000,1,$X$2:$X$10000,">"&$X27)+1 -> 2 | X27: =$V27-(ROW()*0.0000000001) -> 4.91
A28: 46265 | B28: ABMM | C28: ABM INVESTAMA Tbk | D28: PT TIARA MARGA TRAKINDO | E28: Corporate | F28: L | H28: INDONESIA | I28: 1474573133 | J28: 0 | K28: 1474573133 | L28: 53.56 | M28: =IFERROR(_xlfn.XLOOKUP($B28,'Ownership Metrics'!$A:$A,'Ownership Metrics'!$B:$B),"") -> 11.77 | N28: =IFERROR(_xlfn.XLOOKUP($B28,'Ownership Metrics'!$A:$A,'Ownership Metrics'!$C:$C),"") -> 3564 | O28: =IFERROR(_xlfn.XLOOKUP($B28,'Ownership Metrics'!$A:$A,'Ownership Metrics'!$D:$D),"") -> 53.56 | P28: =IFERROR(_xlfn.XLOOKUP($B28,'Ownership Metrics'!$A:$A,'Ownership Metrics'!$E:$E),"") -> 84.73 | Q28: =IFERROR(_xlfn.XLOOKUP($B28,'Ownership Metrics'!$A:$A,'Ownership Metrics'!$F:$F),"") -> 4 | R28: =IFERROR(_xlfn.XLOOKUP($B28,'Ownership Metrics'!$A:$A,'Ownership Metrics'!$G:$G),"") -> 63 | S28: =IFERROR(_xlfn.XLOOKUP($B28,'Ownership Metrics'!$A:$A,'Ownership Metrics'!$H:$H),"") -> Mayoritas | T28: =IFERROR(_xlfn.XLOOKUP($B28,'Ownership Metrics'!$A:$A,'Ownership Metrics'!$I:$I),"") -> Tinggi | U28: =IF(COUNTIFS($B$2:$B28,$B28,$D$2:$D28,$D28)=1,1,0) -> 1 | V28: =SUMIFS($L$2:$L$10000,$B$2:$B$10000,$B28,$D$2:$D$10000,$D28) -> 53.56 | W28: =COUNTIFS($B$2:$B$10000,$B28,$U$2:$U$10000,1,$X$2:$X$10000,">"&$X28)+1 -> 1 | X28: =$V28-(ROW()*0.0000000001) -> 53.56
A29: 46265 | B29: ABMM | C29: ABM INVESTAMA Tbk | D29: NOBLE INVESTMENT CORPORATION (SPC) LTD. | E29: Mutual Funds | F29: F | H29: CAYMAN ISLANDS | I29: 96446100 | J29: 0 | K29: 96446100 | L29: 3.5 | M29: =IFERROR(_xlfn.XLOOKUP($B29,'Ownership Metrics'!$A:$A,'Ownership Metrics'!$B:$B),"") -> 11.77 | N29: =IFERROR(_xlfn.XLOOKUP($B29,'Ownership Metrics'!$A:$A,'Ownership Metrics'!$C:$C),"") -> 3564 | O29: =IFERROR(_xlfn.XLOOKUP($B29,'Ownership Metrics'!$A:$A,'Ownership Metrics'!$D:$D),"") -> 53.56 | P29: =IFERROR(_xlfn.XLOOKUP($B29,'Ownership Metrics'!$A:$A,'Ownership Metrics'!$E:$E),"") -> 84.73 | Q29: =IFERROR(_xlfn.XLOOKUP($B29,'Ownership Metrics'!$A:$A,'Ownership Metrics'!$F:$F),"") -> 4 | R29: =IFERROR(_xlfn.XLOOKUP($B29,'Ownership Metrics'!$A:$A,'Ownership Metrics'!$G:$G),"") -> 63 | S29: =IFERROR(_xlfn.XLOOKUP($B29,'Ownership Metrics'!$A:$A,'Ownership Metrics'!$H:$H),"") -> Mayoritas | T29: =IFERROR(_xlfn.XLOOKUP($B29,'Ownership Metrics'!$A:$A,'Ownership Metrics'!$I:$I),"") -> Tinggi | U29: =IF(COUNTIFS($B$2:$B29,$B29,$D$2:$D29,$D29)=1,1,0) -> 1 | V29: =SUMIFS($L$2:$L$10000,$B$2:$B$10000,$B29,$D$2:$D$10000,$D29) -> 3.5 | W29: =COUNTIFS($B$2:$B$10000,$B29,$U$2:$U$10000,1,$X$2:$X$10000,">"&$X29)+1 -> 4 | X29: =$V29-(ROW()*0.0000000001) -> 3.5
A30: 46265 | B30: ABMM | C30: ABM INVESTAMA Tbk | D30: VALLE VERDE PTE LTD | E30: Firm | F30: F | H30: SINGAPORE | I30: 702349867 | J30: 0 | K30: 702349867 | L30: 25.51 | M30: =IFERROR(_xlfn.XLOOKUP($B30,'Ownership Metrics'!$A:$A,'Ownership Metrics'!$B:$B),"") -> 11.77 | N30: =IFERROR(_xlfn.XLOOKUP($B30,'Ownership Metrics'!$A:$A,'Ownership Metrics'!$C:$C),"") -> 3564 | O30: =IFERROR(_xlfn.XLOOKUP($B30,'Ownership Metrics'!$A:$A,'Ownership Metrics'!$D:$D),"") -> 53.56 | P30: =IFERROR(_xlfn.XLOOKUP($B30,'Ownership Metrics'!$A:$A,'Ownership Metrics'!$E:$E),"") -> 84.73 | Q30: =IFERROR(_xlfn.XLOOKUP($B30,'Ownership Metrics'!$A:$A,'Ownership Metrics'!$F:$F),"") -> 4 | R30: =IFERROR(_xlfn.XLOOKUP($B30,'Ownership Metrics'!$A:$A,'Ownership Metrics'!$G:$G),"") -> 63 | S30: =IFERROR(_xlfn.XLOOKUP($B30,'Ownership Metrics'!$A:$A,'Ownership Metrics'!$H:$H),"") -> Mayoritas | T30: =IFERROR(_xlfn.XLOOKUP($B30,'Ownership Metrics'!$A:$A,'Ownership Metrics'!$I:$I),"") -> Tinggi | U30: =IF(COUNTIFS($B$2:$B30,$B30,$D$2:$D30,$D30)=1,1,0) -> 1 | V30: =SUMIFS($L$2:$L$10000,$B$2:$B$10000,$B30,$D$2:$D$10000,$D30) -> 25.51 | W30: =COUNTIFS($B$2:$B$10000,$B30,$U$2:$U$10000,1,$X$2:$X$10000,">"&$X30)+1 -> 2 | X30: =$V30-(ROW()*0.0000000001) -> 25.51
A31: 46265 | B31: ABMM | C31: ABM INVESTAMA Tbk | D31: DRS LO KHENG HONG | E31: Individual | F31: L | G31: INDONESIAN | H31: INDONESIA | I31: 155929500 | J31: 0 | K31: 155929500 | L31: 5.66 | M31: =IFERROR(_xlfn.XLOOKUP($B31,'Ownership Metrics'!$A:$A,'Ownership Metrics'!$B:$B),"") -> 11.77 | N31: =IFERROR(_xlfn.XLOOKUP($B31,'Ownership Metrics'!$A:$A,'Ownership Metrics'!$C:$C),"") -> 3564 | O31: =IFERROR(_xlfn.XLOOKUP($B31,'Ownership Metrics'!$A:$A,'Ownership Metrics'!$D:$D),"") -> 53.56 | P31: =IFERROR(_xlfn.XLOOKUP($B31,'Ownership Metrics'!$A:$A,'Ownership Metrics'!$E:$E),"") -> 84.73 | Q31: =IFERROR(_xlfn.XLOOKUP($B31,'Ownership Metrics'!$A:$A,'Ownership Metrics'!$F:$F),"") -> 4 | R31: =IFERROR(_xlfn.XLOOKUP($B31,'Ownership Metrics'!$A:$A,'Ownership Metrics'!$G:$G),"") -> 63 | S31: =IFERROR(_xlfn.XLOOKUP($B31,'Ownership Metrics'!$A:$A,'Ownership Metrics'!$H:$H),"") -> Mayoritas | T31: =IFERROR(_xlfn.XLOOKUP($B31,'Ownership Metrics'!$A:$A,'Ownership Metrics'!$I:$I),"") -> Tinggi | U31: =IF(COUNTIFS($B$2:$B31,$B31,$D$2:$D31,$D31)=1,1,0) -> 1 | V31: =SUMIFS($L$2:$L$10000,$B$2:$B$10000,$B31,$D$2:$D$10000,$D31) -> 5.66 | W31: =COUNTIFS($B$2:$B$10000,$B31,$U$2:$U$10000,1,$X$2:$X$10000,">"&$X31)+1 -> 3 | X31: =$V31-(ROW()*0.0000000001) -> 5.66
A32: 46265 | B32: ACES | C32: ASPIRASI HIDUP INDONESIA Tbk | D32: PT KAWAN LAMA SEJAHTERA | E32: Corporate | F32: L | H32: INDONESIA | I32: 10272189700 | J32: 0 | K32: 10272189700 | L32: 60 | M32: =IFERROR(_xlfn.XLOOKUP($B32,'Ownership Metrics'!$A:$A,'Ownership Metrics'!$B:$B),"") -> 34.69 | N32: =IFERROR(_xlfn.XLOOKUP($B32,'Ownership Metrics'!$A:$A,'Ownership Metrics'!$C:$C),"") -> 3611 | O32: =IFERROR(_xlfn.XLOOKUP($B32,'Ownership Metrics'!$A:$A,'Ownership Metrics'!$D:$D),"") -> 60 | P32: =IFERROR(_xlfn.XLOOKUP($B32,'Ownership Metrics'!$A:$A,'Ownership Metrics'!$E:$E),"") -> 64.16 | Q32: =IFERROR(_xlfn.XLOOKUP($B32,'Ownership Metrics'!$A:$A,'Ownership Metrics'!$F:$F),"") -> 4 | R32: =IFERROR(_xlfn.XLOOKUP($B32,'Ownership Metrics'!$A:$A,'Ownership Metrics'!$G:$G),"") -> 56 | S32: =IFERROR(_xlfn.XLOOKUP($B32,'Ownership Metrics'!$A:$A,'Ownership Metrics'!$H:$H),"") -> Mayoritas | T32: =IFERROR(_xlfn.XLOOKUP($B32,'Ownership Metrics'!$A:$A,'Ownership Metrics'!$I:$I),"") -> Tinggi | U32: =IF(COUNTIFS($B$2:$B32,$B32,$D$2:$D32,$D32)=1,1,0) -> 1 | V32: =SUMIFS($L$2:$L$10000,$B$2:$B$10000,$B32,$D$2:$D$10000,$D32) -> 60 | W32: =COUNTIFS($B$2:$B$10000,$B32,$U$2:$U$10000,1,$X$2:$X$10000,">"&$X32)+1 -> 1 | X32: =$V32-(ROW()*0.0000000001) -> 60
A33: 46265 | B33: ACES | C33: ASPIRASI HIDUP INDONESIA Tbk | D33: MERCER QIF FUND PLC | E33: Mutual Funds | F33: F | H33: IRELAND | I33: 196536000 | J33: 0 | K33: 196536000 | L33: 1.15 | M33: =IFERROR(_xlfn.XLOOKUP($B33,'Ownership Metrics'!$A:$A,'Ownership Metrics'!$B:$B),"") -> 34.69 | N33: =IFERROR(_xlfn.XLOOKUP($B33,'Ownership Metrics'!$A:$A,'Ownership Metrics'!$C:$C),"") -> 3611 | O33: =IFERROR(_xlfn.XLOOKUP($B33,'Ownership Metrics'!$A:$A,'Ownership Metrics'!$D:$D),"") -> 60 | P33: =IFERROR(_xlfn.XLOOKUP($B33,'Ownership Metrics'!$A:$A,'Ownership Metrics'!$E:$E),"") -> 64.16 | Q33: =IFERROR(_xlfn.XLOOKUP($B33,'Ownership Metrics'!$A:$A,'Ownership Metrics'!$F:$F),"") -> 4 | R33: =IFERROR(_xlfn.XLOOKUP($B33,'Ownership Metrics'!$A:$A,'Ownership Metrics'!$G:$G),"") -> 56 | S33: =IFERROR(_xlfn.XLOOKUP($B33,'Ownership Metrics'!$A:$A,'Ownership Metrics'!$H:$H),"") -> Mayoritas | T33: =IFERROR(_xlfn.XLOOKUP($B33,'Ownership Metrics'!$A:$A,'Ownership Metrics'!$I:$I),"") -> Tinggi | U33: =IF(COUNTIFS($B$2:$B33,$B33,$D$2:$D33,$D33)=1,1,0) -> 1 | V33: =SUMIFS($L$2:$L$10000,$B$2:$B$10000,$B33,$D$2:$D$10000,$D33) -> 1.15 | W33: =COUNTIFS($B$2:$B$10000,$B33,$U$2:$U$10000,1,$X$2:$X$10000,">"&$X33)+1 -> 4 | X33: =$V33-(ROW()*0.0000000001) -> 1.15
A34: 46265 | B34: ACES | C34: ASPIRASI HIDUP INDONESIA Tbk | D34: ALBIZIA ASEAN OPPORTUNITIES FUND | E34: Mutual Funds | F34: F | H34: CAYMAN ISLANDS | I34: 488996500 | J34: 0 | K34: 488996500 | L34: 2.86 | M34: =IFERROR(_xlfn.XLOOKUP($B34,'Ownership Metrics'!$A:$A,'Ownership Metrics'!$B:$B),"") -> 34.69 | N34: =IFERROR(_xlfn.XLOOKUP($B34,'Ownership Metrics'!$A:$A,'Ownership Metrics'!$C:$C),"") -> 3611 | O34: =IFERROR(_xlfn.XLOOKUP($B34,'Ownership Metrics'!$A:$A,'Ownership Metrics'!$D:$D),"") -> 60 | P34: =IFERROR(_xlfn.XLOOKUP($B34,'Ownership Metrics'!$A:$A,'Ownership Metrics'!$E:$E),"") -> 64.16 | Q34: =IFERROR(_xlfn.XLOOKUP($B34,'Ownership Metrics'!$A:$A,'Ownership Metrics'!$F:$F),"") -> 4 | R34: =IFERROR(_xlfn.XLOOKUP($B34,'Ownership Metrics'!$A:$A,'Ownership Metrics'!$G:$G),"") -> 56 | S34: =IFERROR(_xlfn.XLOOKUP($B34,'Ownership Metrics'!$A:$A,'Ownership Metrics'!$H:$H),"") -> Mayoritas | T34: =IFERROR(_xlfn.XLOOKUP($B34,'Ownership Metrics'!$A:$A,'Ownership Metrics'!$I:$I),"") -> Tinggi | U34: =IF(COUNTIFS($B$2:$B34,$B34,$D$2:$D34,$D34)=1,1,0) -> 1 | V34: =SUMIFS($L$2:$L$10000,$B$2:$B$10000,$B34,$D$2:$D$10000,$D34) -> 2.86 | W34: =COUNTIFS($B$2:$B$10000,$B34,$U$2:$U$10000,1,$X$2:$X$10000,">"&$X34)+1 -> 2 | X34: =$V34-(ROW()*0.0000000001) -> 2.86
A35: 46265 | B35: ACES | C35: ASPIRASI HIDUP INDONESIA Tbk | D35: NT TST CO S/A EDGBASTON ASIAN EQUITY (JERSEY) TRUST | E35: Investment Advisors | F35: F | H35: JERSEY | I35: 222955600 | J35: 0 | K35: 222955600 | L35: 1.3 | M35: =IFERROR(_xlfn.XLOOKUP($B35,'Ownership Metrics'!$A:$A,'Ownership Metrics'!$B:$B),"") -> 34.69 | N35: =IFERROR(_xlfn.XLOOKUP($B35,'Ownership Metrics'!$A:$A,'Ownership Metrics'!$C:$C),"") -> 3611 | O35: =IFERROR(_xlfn.XLOOKUP($B35,'Ownership Metrics'!$A:$A,'Ownership Metrics'!$D:$D),"") -> 60 | P35: =IFERROR(_xlfn.XLOOKUP($B35,'Ownership Metrics'!$A:$A,'Ownership Metrics'!$E:$E),"") -> 64.16 | Q35: =IFERROR(_xlfn.XLOOKUP($B35,'Ownership Metrics'!$A:$A,'Ownership Metrics'!$F:$F),"") -> 4 | R35: =IFERROR(_xlfn.XLOOKUP($B35,'Ownership Metrics'!$A:$A,'Ownership Metrics'!$G:$G),"") -> 56 | S35: =IFERROR(_xlfn.XLOOKUP($B35,'Ownership Metrics'!$A:$A,'Ownership Metrics'!$H:$H),"") -> Mayoritas | T35: =IFERROR(_xlfn.XLOOKUP($B35,'Ownership Metrics'!$A:$A,'Ownership Metrics'!$I:$I),"") -> Tinggi | U35: =IF(COUNTIFS($B$2:$B35,$B35,$D$2:$D35,$D35)=1,1,0) -> 1 | V35: =SUMIFS($L$2:$L$10000,$B$2:$B$10000,$B35,$D$2:$D$10000,$D35) -> 1.3 | W35: =COUNTIFS($B$2:$B$10000,$B35,$U$2:$U$10000,1,$X$2:$X$10000,">"&$X35)+1 -> 3 | X35: =$V35-(ROW()*0.0000000001) -> 1.3
A36: 46265 | B36: ACRO | C36: SAMCRO HYOSUNG ADILESTARI Tbk | D36: JOO HEE KO | E36: Individual | F36: F | G36: SOUTH KOREAN | H36: INDONESIA | I36: 155459000 | J36: 0 | K36: 155459000 | L36: 4.48 | M36: =IFERROR(_xlfn.XLOOKUP($B36,'Ownership Metrics'!$A:$A,'Ownership Metrics'!$B:$B),"") -> 10.23 | N36: =IFERROR(_xlfn.XLOOKUP($B36,'Ownership Metrics'!$A:$A,'Ownership Metrics'!$C:$C),"") -> 6191 | O36: =IFERROR(_xlfn.XLOOKUP($B36,'Ownership Metrics'!$A:$A,'Ownership Metrics'!$D:$D),"") -> 78.4 | P36: =IFERROR(_xlfn.XLOOKUP($B36,'Ownership Metrics'!$A:$A,'Ownership Metrics'!$E:$E),"") -> 86.67 | Q36: =IFERROR(_xlfn.XLOOKUP($B36,'Ownership Metrics'!$A:$A,'Ownership Metrics'!$F:$F),"") -> 4 | R36: =IFERROR(_xlfn.XLOOKUP($B36,'Ownership Metrics'!$A:$A,'Ownership Metrics'!$G:$G),"") -> 75 | S36: =IFERROR(_xlfn.XLOOKUP($B36,'Ownership Metrics'!$A:$A,'Ownership Metrics'!$H:$H),"") -> Mayoritas | T36: =IFERROR(_xlfn.XLOOKUP($B36,'Ownership Metrics'!$A:$A,'Ownership Metrics'!$I:$I),"") -> Tinggi | U36: =IF(COUNTIFS($B$2:$B36,$B36,$D$2:$D36,$D36)=1,1,0) -> 1 | V36: =SUMIFS($L$2:$L$10000,$B$2:$B$10000,$B36,$D$2:$D$10000,$D36) -> 4.48 | W36: =COUNTIFS($B$2:$B$10000,$B36,$U$2:$U$10000,1,$X$2:$X$10000,">"&$X36)+1 -> 2 | X36: =$V36-(ROW()*0.0000000001) -> 4.48
A37: 46265 | B37: ACRO | C37: SAMCRO HYOSUNG ADILESTARI Tbk | D37: SUMAN KIM | E37: Individual | F37: F | G37: SOUTH KOREAN | H37: INDONESIA | I37: 131628700 | J37: 0 | K37: 131628700 | L37: 3.79 | M37: =IFERROR(_xlfn.XLOOKUP($B37,'Ownership Metrics'!$A:$A,'Ownership Metrics'!$B:$B),"") -> 10.23 | N37: =IFERROR(_xlfn.XLOOKUP($B37,'Ownership Metrics'!$A:$A,'Ownership Metrics'!$C:$C),"") -> 6191 | O37: =IFERROR(_xlfn.XLOOKUP($B37,'Ownership Metrics'!$A:$A,'Ownership Metrics'!$D:$D),"") -> 78.4 | P37: =IFERROR(_xlfn.XLOOKUP($B37,'Ownership Metrics'!$A:$A,'Ownership Metrics'!$E:$E),"") -> 86.67 | Q37: =IFERROR(_xlfn.XLOOKUP($B37,'Ownership Metrics'!$A:$A,'Ownership Metrics'!$F:$F),"") -> 4 | R37: =IFERROR(_xlfn.XLOOKUP($B37,'Ownership Metrics'!$A:$A,'Ownership Metrics'!$G:$G),"") -> 75 | S37: =IFERROR(_xlfn.XLOOKUP($B37,'Ownership Metrics'!$A:$A,'Ownership Metrics'!$H:$H),"") -> Mayoritas | T37: =IFERROR(_xlfn.XLOOKUP($B37,'Ownership Metrics'!$A:$A,'Ownership Metrics'!$I:$I),"") -> Tinggi | U37: =IF(COUNTIFS($B$2:$B37,$B37,$D$2:$D37,$D37)=1,1,0) -> 1 | V37: =SUMIFS($L$2:$L$10000,$B$2:$B$10000,$B37,$D$2:$D$10000,$D37) -> 3.79 | W37: =COUNTIFS($B$2:$B$10000,$B37,$U$2:$U$10000,1,$X$2:$X$10000,">"&$X37)+1 -> 3 | X37: =$V37-(ROW()*0.0000000001) -> 3.79
A38: 46265 | B38: ACRO | C38: SAMCRO HYOSUNG ADILESTARI Tbk | D38: KYUNGHEE KO | E38: Individual | F38: F | G38: SOUTH KOREAN | H38: INDONESIA | I38: 107563300 | J38: 0 | K38: 107563300 | L38: 3.1 | M38: =IFERROR(_xlfn.XLOOKUP($B38,'Ownership Metrics'!$A:$A,'Ownership Metrics'!$B:$B),"") -> 10.23 | N38: =IFERROR(_xlfn.XLOOKUP($B38,'Ownership Metrics'!$A:$A,'Ownership Metrics'!$C:$C),"") -> 6191 | O38: =IFERROR(_xlfn.XLOOKUP($B38,'Ownership Metrics'!$A:$A,'Ownership Metrics'!$D:$D),"") -> 78.4 | P38: =IFERROR(_xlfn.XLOOKUP($B38,'Ownership Metrics'!$A:$A,'Ownership Metrics'!$E:$E),"") -> 86.67 | Q38: =IFERROR(_xlfn.XLOOKUP($B38,'Ownership Metrics'!$A:$A,'Ownership Metrics'!$F:$F),"") -> 4 | R38: =IFERROR(_xlfn.XLOOKUP($B38,'Ownership Metrics'!$A:$A,'Ownership Metrics'!$G:$G),"") -> 75 | S38: =IFERROR(_xlfn.XLOOKUP($B38,'Ownership Metrics'!$A:$A,'Ownership Metrics'!$H:$H),"") -> Mayoritas | T38: =IFERROR(_xlfn.XLOOKUP($B38,'Ownership Metrics'!$A:$A,'Ownership Metrics'!$I:$I),"") -> Tinggi | U38: =IF(COUNTIFS($B$2:$B38,$B38,$D$2:$D38,$D38)=1,1,0) -> 1 | V38: =SUMIFS($L$2:$L$10000,$B$2:$B$10000,$B38,$D$2:$D$10000,$D38) -> 3.1 | W38: =COUNTIFS($B$2:$B$10000,$B38,$U$2:$U$10000,1,$X$2:$X$10000,">"&$X38)+1 -> 4 | X38: =$V38-(ROW()*0.0000000001) -> 3.1
A39: 46265 | B39: ACRO | C39: SAMCRO HYOSUNG ADILESTARI Tbk | D39: TAE SUNG CHUNG | E39: Individual | F39: F | G39: SOUTH KOREAN | H39: INDONESIA | I39: 2720072495 | J39: 0 | K39: 2720072495 | L39: 78.4 | M39: =IFERROR(_xlfn.XLOOKUP($B39,'Ownership Metrics'!$A:$A,'Ownership Metrics'!$B:$B),"") -> 10.23 | N39: =IFERROR(_xlfn.XLOOKUP($B39,'Ownership Metrics'!$A:$A,'Ownership Metrics'!$C:$C),"") -> 6191 | O39: =IFERROR(_xlfn.XLOOKUP($B39,'Ownership Metrics'!$A:$A,'Ownership Metrics'!$D:$D),"") -> 78.4 | P39: =IFERROR(_xlfn.XLOOKUP($B39,'Ownership Metrics'!$A:$A,'Ownership Metrics'!$E:$E),"") -> 86.67 | Q39: =IFERROR(_xlfn.XLOOKUP($B39,'Ownership Metrics'!$A:$A,'Ownership Metrics'!$F:$F),"") -> 4 | R39: =IFERROR(_xlfn.XLOOKUP($B39,'Ownership Metrics'!$A:$A,'Ownership Metrics'!$G:$G),"") -> 75 | S39: =IFERROR(_xlfn.XLOOKUP($B39,'Ownership Metrics'!$A:$A,'Ownership Metrics'!$H:$H),"") -> Mayoritas | T39: =IFERROR(_xlfn.XLOOKUP($B39,'Ownership Metrics'!$A:$A,'Ownership Metrics'!$I:$I),"") -> Tinggi | U39: =IF(COUNTIFS($B$2:$B39,$B39,$D$2:$D39,$D39)=1,1,0) -> 1 | V39: =SUMIFS($L$2:$L$10000,$B$2:$B$10000,$B39,$D$2:$D$10000,$D39) -> 78.4 | W39: =COUNTIFS($B$2:$B$10000,$B39,$U$2:$U$10000,1,$X$2:$X$10000,">"&$X39)+1 -> 1 | X39: =$V39-(ROW()*0.0000000001) -> 78.4
A40: 46265 | B40: ACST | C40: ACSET INDONUSA Tbk | D40: PT. KARYA SUPRA PERKASA | E40: Corporate | F40: L | H40: INDONESIA | I40: 16115027968 | J40: 0 | K40: 16115027968 | L40: 91.17 | M40: =IFERROR(_xlfn.XLOOKUP($B40,'Ownership Metrics'!$A:$A,'Ownership Metrics'!$B:$B),"") -> 8.83 | N40: =IFERROR(_xlfn.XLOOKUP($B40,'Ownership Metrics'!$A:$A,'Ownership Metrics'!$C:$C),"") -> 8312 | O40: =IFERROR(_xlfn.XLOOKUP($B40,'Ownership Metrics'!$A:$A,'Ownership Metrics'!$D:$D),"") -> 91.17 | P40: =IFERROR(_xlfn.XLOOKUP($B40,'Ownership Metrics'!$A:$A,'Ownership Metrics'!$E:$E),"") -> 91.17 | Q40: =IFERROR(_xlfn.XLOOKUP($B40,'Ownership Metrics'!$A:$A,'Ownership Metrics'!$F:$F),"") -> 1 | R40: =IFERROR(_xlfn.XLOOKUP($B40,'Ownership Metrics'!$A:$A,'Ownership Metrics'!$G:$G),"") -> 89 | S40: =IFERROR(_xlfn.XLOOKUP($B40,'Ownership Metrics'!$A:$A,'Ownership Metrics'!$H:$H),"") -> Mayoritas | T40: =IFERROR(_xlfn.XLOOKUP($B40,'Ownership Metrics'!$A:$A,'Ownership Metrics'!$I:$I),"") -> Tinggi | U40: =IF(COUNTIFS($B$2:$B40,$B40,$D$2:$D40,$D40)=1,1,0) -> 1 | V40: =SUMIFS($L$2:$L$10000,$B$2:$B$10000,$B40,$D$2:$D$10000,$D40) -> 91.17 | W40: =COUNTIFS($B$2:$B$10000,$B40,$U$2:$U$10000,1,$X$2:$X$10000,">"&$X40)+1 -> 1 | X40: =$V40-(ROW()*0.0000000001) -> 91.17
...

Sheet OWNERSHIP CLASSIFICATION
A1: Date | B1: Ticker | C1: Company Name | D1: Bank | E1: Government | F1: Private Equity | G1: Trustee Bank | H1: Venture Capital | I1: Private Bank | J1: Exchange Traded Funds | K1: Investment Manager | L1: Investment Advisors | M1: Brokerage Firms | N1: Hedge Fund | O1: Sovereign Wealth Fund | P1: Capital Market Supporting Institutions and Professions | Q1: Commanditaire Vennootschap (CV) or Limited Partnership | R1: Firm | S1: Investment Fund Selling Agent | T1: Peer to Peer Lending | U1: Permanent Establishment | V1: Sole Proprietorship | W1: Corporate | X1: Association/Social Organizations | Y1: State Owned Enterprises | Z1: Central Bank | AA1: State Owned Company | AB1: Diocese | AC1: Conference | AD1: Congregation | AE1: Cooperatives | AF1: International Organization | AG1: Political Parties | AH1: Partnership | AI1: Educational Institution | AJ1: Mutual Funds (MF) | AK1: Securities Company (SC) | AL1: Pension Funds (PF) | AM1: Financial Institutional (IB) | AN1: Insurance (IS) | AO1: Foundation (FD) | AP1: Individual (ID) | AQ1: Total Scripless
A2: 46265 | B2: AADI | C2: ADARO ANDALAN INDONESIA Tbk | D2: 22689622 | E2: 2445800 | F2: 15534069 | G2: 14091457 | H2: 279109 | I2: 407745164 | J2: 74101165 | K2: 902068 | L2: 43202412 | M2: 1001874 | N2: 1511900 | O2: 5548173 | P2: 3431914 | Q2: 7896556 | R2: 9310345 | S2: 0 | T2: 0 | U2: 0 | V2: 2600 | W2: 4767324914 | X2: 117700 | Y2: 0 | Z2: 6906800 | AA2: 238400 | AB2: 0 | AC2: 0 | AD2: 0 | AE2: 75 | AF2: 0 | AG2: 0 | AH2: 1361600 | AI2: 112506 | AJ2: 375253695 | AK2: 25532845 | AL2: 50398966 | AM2: 112444141 | AN2: 129761778 | AO2: 2732997 | AP2: 1705011115 | AQ2: 7786891760
A3: 46265 | B3: AALI | C3: ASTRA AGRO LESTARI Tbk | D3: 17637913 | E3: 1706710 | F3: 665700 | G3: 444300 | H3: 0 | I3: 7986754 | J3: 3191010 | K3: 1092664 | L3: 20600401 | M3: 2442862 | N3: 461000 | O3: 1938458 | P3: 867079 | Q3: 2469300 | R3: 923700 | S3: 0 | T3: 0 | U3: 0 | V3: 0 | W3: 28382779 | X3: 0 | Y3: 13683700 | Z3: 103500 | AA3: 0 | AB3: 0 | AC3: 0 | AD3: 0 | AE3: 7800 | AF3: 0 | AG3: 0 | AH3: 4747227 | AI3: 0 | AJ3: 51282467 | AK3: 3963986 | AL3: 25024332 | AM3: 246036 | AN3: 59061116 | AO3: 4213312 | AP3: 137652987 | AQ3: 390797093
A4: 46265 | B4: ABBA | C4: MAHAKA MEDIA Tbk | D4: 629886 | E4: 0 | F4: 1593331618 | G4: 0 | H4: 0 | I4: 1690100 | J4: 0 | K4: 0 | L4: 77100 | M4: 0 | N4: 0 | O4: 0 | P4: 0 | Q4: 0 | R4: 46247699 | S4: 0 | T4: 0 | U4: 0 | V4: 0 | W4: 728542388 | X4: 0 | Y4: 0 | Z4: 0 | AA4: 0 | AB4: 0 | AC4: 0 | AD4: 0 | AE4: 0 | AF4: 0 | AG4: 0 | AH4: 0 | AI4: 0 | AJ4: 0 | AK4: 1754780 | AL4: 0 | AM4: 39999999 | AN4: 0 | AO4: 71 | AP4: 1065382715 | AQ4: 3477656356
A5: 46265 | B5: ABDA | C5: ASURANSI BINA DANA ARTA Tbk | D5: 3598 | E5: 20 | F5: 21750171 | G5: 0 | H5: 0 | I5: 28002100 | J5: 0 | K5: 0 | L5: 516 | M5: 0 | N5: 0 | O5: 0 | P5: 0 | Q5: 0 | R5: 0 | S5: 0 | T5: 0 | U5: 0 | V5: 0 | W5: 32120 | X5: 0 | Y5: 0 | Z5: 0 | AA5: 0 | AB5: 0 | AC5: 0 | AD5: 0 | AE5: 0 | AF5: 0 | AG5: 0 | AH5: 0 | AI5: 0 | AJ5: 0 | AK5: 30511250 | AL5: 0 | AM5: 0 | AN5: 538604204 | AO5: 422334 | AP5: 442757 | AQ5: 619769070
